<?xml version="1.0" ?>
<!-- =================================================================================== -->
<!-- |    This document was autogenerated by xacro from cassie_simple.xacro            | -->
<!-- |    EDITING THIS FILE BY HAND IS NOT RECOMMENDED                                 | -->
<!-- =================================================================================== -->
<!-- University of Michigan 
     Author: Ross Hartley
     Email:  rosshart@umich.edu
     Date:   12/14/2016   -->
<robot name="cassie_simple" xmlns:xacro="http://ros.org/wiki/xacro">
  <link name="pelvis">
    <inertial>
      <origin rpy="0 0 0" xyz=".0507 0 .0284"/>
      <mass value="10.33"/>
      <inertia ixx=".0942" ixy=".000169" ixz=".015" iyy=".084" iyz=".000516" izz=".113"/>
    </inertial>
    <visual>
      <origin rpy="0 0 0" xyz="0 0 0"/>
      <geometry>
        <mesh filename="package://cassie_description/meshes/pelvis.stl" scale="1 1 1"/>
      </geometry>
      <material name="blue">
        <color rgba=".01569 .11765 .25882 1"/>
      </material>
    </visual>
  </link>
  <link name="left_pelvis_abduction">
    <inertial>
      <origin rpy="0 0 0" xyz="0 0 0"/>
      <mass value="0"/>
      <inertia ixx="0" ixy="0" ixz="0" iyy="0" iyz="0" izz="0"/>
    </inertial>
    <visual>
      <origin rpy="0 0 0" xyz="0 0 0"/>
      <geometry>
        <mesh filename="package://cassie_description/meshes/abduction.stl" scale="1 1 1"/>
      </geometry>
      <material name="maize">
        <color rgba=".945098 .76863 0.0 1"/>
      </material>
    </visual>
  </link>
  <link name="left_pelvis_rotation">
    <inertial>
      <origin rpy="0 0 0" xyz=".0257 0.0001 .0179"/>
      <mass value="1.82"/>
      <inertia ixx=".00272" ixy=".000000703" ixz=".00000153" iyy=".00559" iyz=".00000261" izz=".004640"/>
    </inertial>
    <visual>
      <origin rpy="0 0 0" xyz="0 0 0"/>
      <geometry>
        <mesh filename="package://cassie_description/meshes/yaw.stl" scale="1 1 1"/>
      </geometry>
      <material name="maize">
        <color rgba=".945098 .76863 0.0 1"/>
      </material>
    </visual>
  </link>
  <link name="left_hip">
    <inertial>
      <origin rpy="0 0 0" xyz="-.0557 0 0"/>
      <mass value="1.17"/>
      <inertia ixx=".000842" ixy=".000000246" ixz="-.000000625" iyy=".006080" iyz="-.00000004" izz=".006440"/>
    </inertial>
    <visual>
      <origin rpy="0 0 0" xyz="0 0 0"/>
      <geometry>
        <mesh filename="package://cassie_description/meshes/hip.stl" scale="1 1 1"/>
      </geometry>
      <material name="maize">
        <color rgba=".945098 .76863 0.0 1"/>
      </material>
    </visual>
  </link>
  <link name="left_thigh">
    <inertial>
      <origin rpy="0 0 0" xyz=".0598 .0001 -0.0358"/>
      <mass value="5.52"/>
      <inertia ixx=".018" ixy=".000284" ixz="-.0117" iyy=".0563" iyz="-.0000193" izz=".0498"/>
    </inertial>
    <visual>
      <origin rpy="0 0 0" xyz="0 0 0"/>
      <geometry>
        <mesh filename="package://cassie_description/meshes/thigh.stl" scale="1 1 1"/>
      </geometry>
      <material name="maize">
        <color rgba=".945098 .76863 0.0 1"/>
      </material>
    </visual>
  </link>
  <link name="left_knee">
    <inertial>
      <origin rpy="0 0 0" xyz=".023 .0321 -0.0022"/>
      <mass value=".758"/>
      <inertia ixx=".002160" ixy=".000956" ixz=".00000284" iyy=".00144" iyz=".000000739" izz=".00334"/>
    </inertial>
    <visual>
      <origin rpy="0 0 0" xyz="0 0 0"/>
      <geometry>
        <mesh filename="package://cassie_description/meshes/knee-output.stl" scale="1 1 1"/>
      </geometry>
      <material name="maize">
        <color rgba=".945098 .76863 0.0 1"/>
      </material>
    </visual>
  </link>
  <link name="left_shin">
    <inertial>
      <origin rpy="0 0 0" xyz=".1834 .0012 0.0002"/>
      <mass value=".577"/>
      <inertia ixx=".000360" ixy=".000334" ixz="-.000000194" iyy=".0341" iyz=".000000265" izz=".0341"/>
    </inertial>
    <visual>
      <origin rpy="0 0 0" xyz="0 0 0"/>
      <geometry>
        <mesh filename="package://cassie_description/meshes/shin-bone.stl" scale="1 1 1"/>
      </geometry>
      <material name="blue">
        <color rgba=".01569 .11765 .25882 1"/>
      </material>
    </visual>
  </link>
  <link name="left_tarsus">
    <inertial>
      <origin rpy="0 0 0" xyz=".1105 -.0306 -0.0013"/>
      <mass value=".782"/>
      <inertia ixx=".00113" ixy="-.00288" ixz="-.0000633" iyy=".0231" iyz=".0000362" izz=".0239"/>
    </inertial>
    <visual>
      <origin rpy="0 0 0" xyz="0 0 0"/>
      <geometry>
        <mesh filename="package://cassie_description/meshes/tarsus.stl" scale="1 1 1"/>
      </geometry>
      <material name="blue">
        <color rgba=".01569 .11765 .25882 1"/>
      </material>
    </visual>
  </link>
  <link name="left_toe">
    <inertial>
      <origin rpy="0 0 0" xyz=".0047 .0275 -0.0001"/>
      <mass value=".15"/>
      <inertia ixx=".000287" ixy="-.0000986" ixz="-.00000146" iyy=".000171" iyz=".000000172" izz=".000449"/>
    </inertial>
    <visual>
      <origin rpy="0 0 0" xyz="0 0 0"/>
      <geometry>
        <mesh filename="package://cassie_description/meshes/toe.stl" scale="1 1 1"/>
      </geometry>
      <material name="maize">
        <color rgba=".945098 .76863 0.0 1"/>
      </material>
    </visual>
  </link>
  <link name="right_pelvis_abduction">
    <inertial>
      <origin rpy="0 0 0" xyz="0 0 0"/>
      <mass value="0"/>
      <inertia ixx="0" ixy="0" ixz="0" iyy="0" iyz="0" izz="0"/>
    </inertial>
    <visual>
      <origin rpy="0 0 0" xyz="0 0 0"/>
      <geometry>
        <mesh filename="package://cassie_description/meshes/abduction_mirror.stl" scale="1 1 1"/>
      </geometry>
      <material name="maize">
        <color rgba=".945098 .76863 0.0 1"/>
      </material>
    </visual>
  </link>
  <link name="right_pelvis_rotation">
    <inertial>
      <origin rpy="0 0 0" xyz=".0257 -0.0001 .0179"/>
      <mass value="1.82"/>
      <inertia ixx=".00272" ixy=".000000703" ixz=".00000153" iyy=".00559" iyz=".00000261" izz=".004640"/>
    </inertial>
    <visual>
      <origin rpy="0 0 0" xyz="0 0 0"/>
      <geometry>
        <mesh filename="package://cassie_description/meshes/yaw_mirror.stl" scale="1 1 1"/>
      </geometry>
      <material name="maize">
        <color rgba=".945098 .76863 0.0 1"/>
      </material>
    </visual>
  </link>
  <link name="right_hip">
    <inertial>
      <origin rpy="0 0 0" xyz="-.0557 0 0"/>
      <mass value="1.17"/>
      <inertia ixx=".000842" ixy=".000000246" ixz="-.000000625" iyy=".006080" iyz="-.00000004" izz=".006440"/>
    </inertial>
    <visual>
      <origin rpy="0 0 0" xyz="0 0 0"/>
      <geometry>
        <mesh filename="package://cassie_description/meshes/hip_mirror.stl" scale="1 1 1"/>
      </geometry>
      <material name="maize">
        <color rgba=".945098 .76863 0.0 1"/>
      </material>
    </visual>
  </link>
  <link name="right_thigh">
    <inertial>
      <origin rpy="0 0 0" xyz=".0598 .0001 0.0358"/>
      <mass value="5.52"/>
      <inertia ixx=".018" ixy=".000284" ixz="-.0117" iyy=".0563" iyz="-.0000193" izz=".0498"/>
    </inertial>
    <visual>
      <origin rpy="0 0 0" xyz="0 0 0"/>
      <geometry>
        <mesh filename="package://cassie_description/meshes/thigh_mirror.stl" scale="1 1 1"/>
      </geometry>
      <material name="maize">
        <color rgba=".945098 .76863 0.0 1"/>
      </material>
    </visual>
  </link>
  <link name="right_knee">
    <inertial>
      <origin rpy="0 0 0" xyz=".023 .0321 0.0022"/>
      <mass value=".758"/>
      <inertia ixx=".002160" ixy=".000956" ixz=".00000284" iyy=".00144" iyz=".000000739" izz=".00334"/>
    </inertial>
    <visual>
      <origin rpy="0 0 0" xyz="0 0 0"/>
      <geometry>
        <mesh filename="package://cassie_description/meshes/knee-output_mirror.stl" scale="1 1 1"/>
      </geometry>
      <material name="maize">
        <color rgba=".945098 .76863 0.0 1"/>
      </material>
    </visual>
  </link>
  <link name="right_shin">
    <inertial>
      <origin rpy="0 0 0" xyz=".1834 .0012 -0.0002"/>
      <mass value=".577"/>
      <inertia ixx=".000360" ixy=".000334" ixz="-.000000194" iyy=".0341" iyz=".000000265" izz=".0341"/>
    </inertial>
    <visual>
      <origin rpy="0 0 0" xyz="0 0 0"/>
      <geometry>
        <mesh filename="package://cassie_description/meshes/shin-bone_mirror.stl" scale="1 1 1"/>
      </geometry>
      <material name="blue">
        <color rgba=".01569 .11765 .25882 1"/>
      </material>
    </visual>
  </link>
  <link name="right_tarsus">
    <inertial>
      <origin rpy="0 0 0" xyz=".1105 -.0306 0.0013"/>
      <mass value=".782"/>
      <inertia ixx=".00113" ixy="-.00288" ixz="-.0000633" iyy=".0231" iyz=".0000362" izz=".0239"/>
    </inertial>
    <visual>
      <origin rpy="0 0 0" xyz="0 0 0"/>
      <geometry>
        <mesh filename="package://cassie_description/meshes/tarsus_mirror.stl" scale="1 1 1"/>
      </geometry>
      <material name="blue">
        <color rgba=".01569 .11765 .25882 1"/>
      </material>
    </visual>
  </link>
  <link name="right_toe">
    <inertial>
      <origin rpy="0 0 0" xyz=".0047 .0275 0.0001"/>
      <mass value=".15"/>
      <inertia ixx=".000287" ixy="-.0000986" ixz="-.00000146" iyy=".000171" iyz=".000000172" izz=".000449"/>
    </inertial>
    <visual>
      <origin rpy="0 0 0" xyz="0 0 0"/>
      <geometry>
        <mesh filename="package://cassie_description/meshes/toe_mirror.stl" scale="1 1 1"/>
      </geometry>
      <material name="maize">
        <color rgba=".945098 .76863 0.0 1"/>
      </material>
    </visual>
  </link>
  <joint name="fixed_left" type="fixed">
    <origin rpy="0 1.57079632679 0" xyz="0.021 0.135 0"/>
    <axis xyz="0 0 1"/>
    <parent link="pelvis"/>
    <child link="left_pelvis_abduction"/>
  </joint>
  <joint name="hip_abduction_left" type="continuous">
    <origin rpy="0 -1.57079632679 0" xyz="0 0 -0.07"/>
    <axis xyz="1 0 0"/>
    <parent link="left_pelvis_abduction"/>
    <child link="left_pelvis_rotation"/>
  </joint>
  <joint name="hip_rotation_left" type="continuous">
    <origin rpy="0 1.57079632679 -1.57079632679" xyz="0 0 -0.09"/>
    <axis xyz="1 0 0"/>
    <parent link="left_pelvis_rotation"/>
    <child link="left_hip"/>
  </joint>
  <joint name="hip_flexion_left" type="continuous">
    <origin rpy="0 0 0" xyz="0 0 0"/>
    <axis xyz="0 0 1"/>
    <parent link="left_hip"/>
    <child link="left_thigh"/>
  </joint>
  <joint name="knee_joint_left" type="continuous">
    <origin rpy="0 0 0" xyz="0.12 0 0.0045"/>
    <axis xyz="0 0 1"/>
    <parent link="left_thigh"/>
    <child link="left_knee"/>
  </joint>
  <joint name="fixed_knee_to_shin_left" type="fixed">
    <origin rpy="0 0 0" xyz="0.0607 0.0474 0"/>
    <axis xyz="0 0 1"/>
    <parent link="left_knee"/>
    <child link="left_shin"/>
  </joint>
  <joint name="ankle_joint_left" type="continuous">
    <origin rpy="0 0 0" xyz="0.4348 0.02 0"/>
    <axis xyz="0 0 1"/>
    <parent link="left_shin"/>
    <child link="left_tarsus"/>
  </joint>
  <joint name="toe_joint_left" type="continuous">
    <origin rpy="0 0 0" xyz="0.408 -0.04 0"/>
    <axis xyz="0 0 1"/>
    <parent link="left_tarsus"/>
    <child link="left_toe"/>
  </joint>
  <joint name="fixed_right" type="fixed">
    <origin rpy="0 1.57079632679 0" xyz="0.021 -0.135 0"/>
    <axis xyz="0 0 1"/>
    <parent link="pelvis"/>
    <child link="right_pelvis_abduction"/>
  </joint>
  <joint name="hip_abduction_right" type="continuous">
    <origin rpy="0 -1.57079632679 0" xyz="0 0 -0.07"/>
    <axis xyz="1 0 0"/>
    <parent link="right_pelvis_abduction"/>
    <child link="right_pelvis_rotation"/>
  </joint>
  <joint name="hip_rotation_right" type="continuous">
    <origin rpy="0 1.57079632679 -1.57079632679" xyz="0 0 -0.09"/>
    <axis xyz="1 0 0"/>
    <parent link="right_pelvis_rotation"/>
    <child link="right_hip"/>
  </joint>
  <joint name="hip_flexion_right" type="continuous">
    <origin rpy="0 0 0" xyz="0 0 0"/>
    <axis xyz="0 0 1"/>
    <parent link="right_hip"/>
    <child link="right_thigh"/>
  </joint>
  <joint name="knee_joint_right" type="continuous">
    <origin rpy="0 0 0" xyz="0.12 0 -0.0045"/>
    <axis xyz="0 0 1"/>
    <parent link="right_thigh"/>
    <child link="right_knee"/>
  </joint>
  <joint name="fixed_knee_to_shin_right" type="fixed">
    <origin rpy="0 0 0" xyz="0.0607 0.0474 0"/>
    <axis xyz="0 0 1"/>
    <parent link="right_knee"/>
    <child link="right_shin"/>
  </joint>
  <joint name="ankle_joint_right" type="continuous">
    <origin rpy="0 0 0" xyz="0.4348 0.02 0"/>
    <axis xyz="0 0 1"/>
    <parent link="right_shin"/>
    <child link="right_tarsus"/>
  </joint>
  <joint name="toe_joint_right" type="continuous">
    <origin rpy="0 0 0" xyz="0.408 -0.04 0"/>
    <axis xyz="0 0 1"/>
    <parent link="right_tarsus"/>
    <child link="right_toe"/>
  </joint>
</robot>

